[17:33:33.102 [MainThread] (unknown file) ERROR] error executing main
Traceback (most recent call last):
  File "/usr/lib/python3/dist-packages/sawtooth_validator/server/cli.py", line 290, in main
    validator.stop()
  File "/usr/lib/python3/dist-packages/sawtooth_validator/server/core.py", line 492, in stop
    time.sleep(1)
KeyboardInterrupt
[17:45:46.526 [MainThread] (unknown file) ERROR] error executing main
Traceback (most recent call last):
  File "/usr/lib/python3/dist-packages/sawtooth_validator/server/cli.py", line 290, in main
    validator.stop()
  File "/usr/lib/python3/dist-packages/sawtooth_validator/server/core.py", line 492, in stop
    time.sleep(1)
KeyboardInterrupt
[10:32:43.735 [MainThread] (unknown file) ERROR] error executing main
Traceback (most recent call last):
  File "/usr/lib/python3/dist-packages/sawtooth_validator/server/cli.py", line 290, in main
    validator.stop()
  File "/usr/lib/python3/dist-packages/sawtooth_validator/server/core.py", line 462, in stop
    self._network_thread_pool.shutdown(wait=True)
  File "/usr/lib/python3.5/concurrent/futures/thread.py", line 139, in shutdown
    t.join()
  File "/usr/lib/python3.5/threading.py", line 1054, in join
    self._wait_for_tstate_lock()
  File "/usr/lib/python3.5/threading.py", line 1070, in _wait_for_tstate_lock
    elif lock.acquire(block, timeout):
KeyboardInterrupt
[10:38:40.277 [MainThread] (unknown file) ERROR] error executing main
Traceback (most recent call last):
  File "/usr/lib/python3/dist-packages/sawtooth_validator/server/cli.py", line 290, in main
    validator.stop()
  File "/usr/lib/python3/dist-packages/sawtooth_validator/server/core.py", line 488, in stop
    if not t.is_alive():
  File "/usr/lib/python3.5/threading.py", line 1113, in is_alive
    self._wait_for_tstate_lock(False)
  File "/usr/lib/python3.5/threading.py", line 1069, in _wait_for_tstate_lock
    assert self._is_stopped
AssertionError
