```waiting for solr ...
Enabling realtime indexing ...
>>> YES updating cred type timestamp
>>> YES create detail claims for credentials
Operations to perform:
  Apply all migrations: admin, api_v2, auth, contenttypes, rest_hooks, sessions, subscriptions
Running migrations:
  Applying contenttypes.0001_initial... OK
  Applying contenttypes.0002_remove_content_type_name... OK
  Applying auth.0001_initial... OK
  Applying auth.0002_alter_permission_name_max_length... OK
  Applying auth.0003_alter_user_email_max_length... OK
  Applying auth.0004_alter_user_username_opts... OK
  Applying auth.0005_alter_user_last_login_null... OK
  Applying auth.0006_require_contenttypes_0002... OK
  Applying auth.0007_alter_validators_add_error_messages... OK
  Applying auth.0008_alter_user_username_max_length... OK
  Applying api_v2.0001_initial_user... OK
  Applying admin.0001_initial... OK
  Applying admin.0002_logentry_remove_auto_add... OK
  Applying admin.0003_logentry_add_action_flag_choices... OK
  Applying api_v2.0002_user_display_name... OK
  Applying api_v2.0003_auto_20181005_2140... OK
  Applying api_v2.0004_auto_20190107_2203... OK
  Applying api_v2.0001_initial... OK
  Applying api_v2.0002_category... OK
  Applying api_v2.0003_auto_20180821_1840... OK
  Applying api_v2.0004_auto_20180821_2221... OK
  Applying api_v2.0005_auto_20180824_2256... OK
  Applying api_v2.0006_auto_20180824_2333... OK
  Applying api_v2.0007_auto_20180827_2356... OK
  Applying api_v2.0008_auto_20180829_1902... OK
  Applying api_v2.0009_auto_20180907_1641... OK
  Applying api_v2.0010_auto_20180907_2354... OK
  Applying api_v2.0011_credentialtype_visible_fields... OK
  Applying api_v2.0012_credential_inactive... OK
  Applying api_v2.0013_auto_20180921_1844... OK
  Applying api_v2.0014_auto_20180921_2334... OK
  Applying api_v2.0015_auto_20181025_2152... OK
  Applying api_v2.0016_auto_20181027_1802... OK
  Applying api_v2.0017_auto_20181113_1753... OK
  Applying api_v2.0018_credentialtype_last_issue_date... OK
  Applying api_v2.0019_credentialtype_url... OK
  Applying api_v2.0020_auto_20181207_1925... OK
  Applying api_v2.0021_auto_20190107_2203... OK
  Applying api_v2.0022_auto_20190109_0014... OK
  Applying api_v2.0023_name_type... OK
  Applying api_v2.0023_issuer_endpoint... OK
  Applying api_v2.0024_merge_20190201_1913... OK
  Applying api_v2.0025_auto_20190729_1903... OK
  Applying api_v2.0026_auto_20190923_0217... OK
  Applying api_v2.0027_auto_20200519_2019... OK
  Applying api_v2.0028_credentialtype_metadata... OK
  Applying api_v2.0029_credentialtype_schema_labels... OK
  Applying auth.0009_alter_user_last_name_max_length... OK
  Applying auth.0010_alter_group_name_max_length... OK
  Applying auth.0011_update_proxy_permissions... OK
  Applying rest_hooks.0001_initial... OK
  Applying sessions.0001_initial... OK
  Applying subscriptions.0001_initial... OK
  Applying subscriptions.0002_auto_20190409_1050... OK
  Applying subscriptions.0003_auto_20190412_1916... OK
  Applying subscriptions.0004_auto_20191213_1723... OK
  Applying subscriptions.0005_auto_20191218_2215... OK
  Applying subscriptions.0006_credentialhookstats... OK
Enabling realtime indexing ...
Starting celery with broker pyamqp://RABBITMQ_USER:RABBITMQ_PASSWORD@rabbitmq// and backend db+postgresql://DB_USER:DB_PASSWORD@vcr-db/THE_ORG_BOOK
>>> YES updating cred type timestamp
omoge_real@cloudshell:~/aries-vcr-client/docker$ docker container logs vcr_vcr-api_1 > logs.logs
INFO:snowplow_tracker.emitters:Emitter initialized with endpoint https://spm.apps.gov.bc.ca/i
INFO:snowplow_tracker.emitters:Emitter initialized with endpoint https://spm.apps.gov.bc.ca/i
INFO:snowplow_tracker.emitters:Emitter initialized with endpoint https://spm.apps.gov.bc.ca/i
INFO:snowplow_tracker.emitters:Emitter initialized with endpoint https://spm.apps.gov.bc.ca/i
ERROR 2021-12-03 19:23:54,553 pysolr 121 140304677345024 Solr responded with an error (HTTP 404): [Reason: Error 404 Not Found]
Failed to add documents to Solr: Solr responded with an error (HTTP 404): [Reason: Error 404 Not Found]
Traceback (most recent call last):
  File "/home/indy/agent_webhooks/utils/credential.py", line 444, in find_or_create_topic
    return (Topic.objects.get(**topic_spec), False)
  File "/home/indy/.pyenv/versions/3.6.8/lib/python3.6/site-packages/django/db/models/manager.py", line 82, in manager_method
    return getattr(self.get_queryset(), name)(*args, **kwargs)
  File "/home/indy/.pyenv/versions/3.6.8/lib/python3.6/site-packages/django/db/models/query.py", line 408, in get
    self.model._meta.object_name
api.v2.models.Topic.Topic.DoesNotExist: Topic matching query does not exist.

During handling of the above exception, another exception occurred:

Traceback (most recent call last):
  File "/home/indy/.pyenv/versions/3.6.8/lib/python3.6/site-packages/haystack/backends/solr_backend.py", line 76, in update
    self.conn.add(docs, commit=commit, boost=index.get_field_weights())
  File "/home/indy/.pyenv/versions/3.6.8/lib/python3.6/site-packages/pysolr.py", line 1050, in add
    solrapi=solrapi,
  File "/home/indy/.pyenv/versions/3.6.8/lib/python3.6/site-packages/pysolr.py", line 565, in _update
    "post", path, message, {"Content-type": "text/xml; charset=utf-8"}
  File "/home/indy/.pyenv/versions/3.6.8/lib/python3.6/site-packages/pysolr.py", line 463, in _send_request
    raise SolrError(error_message % (resp.status_code, solr_message))
pysolr.SolrError: Solr responded with an error (HTTP 404): [Reason: Error 404 Not Found]
ERROR 2021-12-03 19:24:58,817 pysolr 121 140304664143616 Solr responded with an error (HTTP 404): [Reason: Error 404 Not Found]
Failed to query Solr using '*:*': Solr responded with an error (HTTP 404): [Reason: Error 404 Not Found]
Traceback (most recent call last):
  File "/home/indy/.pyenv/versions/3.6.8/lib/python3.6/site-packages/haystack/backends/solr_backend.py", line 138, in search
    raw_results = self.conn.search(query_string, **search_kwargs)
  File "/home/indy/.pyenv/versions/3.6.8/lib/python3.6/site-packages/pysolr.py", line 827, in search
    response = self._select(params, handler=search_handler)
  File "/home/indy/.pyenv/versions/3.6.8/lib/python3.6/site-packages/pysolr.py", line 488, in _select
    return self._send_request("get", path)
  File "/home/indy/.pyenv/versions/3.6.8/lib/python3.6/site-packages/pysolr.py", line 463, in _send_request
    raise SolrError(error_message % (resp.status_code, solr_message))
pysolr.SolrError: Solr responded with an error (HTTP 404): [Reason: Error 404 Not Found]
ERROR 2021-12-03 19:24:58,817 solr_backend 121 140304664143616 Failed to query Solr using '*:*': Solr responded with an error (HTTP 404): [Reason: Error 404 Not Found]
Traceback (most recent call last):
  File "/home/indy/.pyenv/versions/3.6.8/lib/python3.6/site-packages/haystack/backends/solr_backend.py", line 138, in search
    raw_results = self.conn.search(query_string, **search_kwargs)
  File "/home/indy/.pyenv/versions/3.6.8/lib/python3.6/site-packages/pysolr.py", line 827, in search
    response = self._select(params, handler=search_handler)
  File "/home/indy/.pyenv/versions/3.6.8/lib/python3.6/site-packages/pysolr.py", line 488, in _select
    return self._send_request("get", path)
  File "/home/indy/.pyenv/versions/3.6.8/lib/python3.6/site-packages/pysolr.py", line 463, in _send_request
    raise SolrError(error_message % (resp.status_code, solr_message))
pysolr.SolrError: Solr responded with an error (HTTP 404): [Reason: Error 404 Not Found]
ERROR 2021-12-03 19:24:58,857 pysolr 121 140304664143616 Solr responded with an error (HTTP 404): [Reason: Error 404 Not Found]
Failed to query Solr using 'latest:(true)': Solr responded with an error (HTTP 404): [Reason: Error 404 Not Found]
Traceback (most recent call last):
  File "/home/indy/.pyenv/versions/3.6.8/lib/python3.6/site-packages/haystack/backends/solr_backend.py", line 138, in search
    raw_results = self.conn.search(query_string, **search_kwargs)
  File "/home/indy/.pyenv/versions/3.6.8/lib/python3.6/site-packages/pysolr.py", line 827, in search
    response = self._select(params, handler=search_handler)
  File "/home/indy/.pyenv/versions/3.6.8/lib/python3.6/site-packages/pysolr.py", line 488, in _select
    return self._send_request("get", path)
  File "/home/indy/.pyenv/versions/3.6.8/lib/python3.6/site-packages/pysolr.py", line 463, in _send_request
    raise SolrError(error_message % (resp.status_code, solr_message))
pysolr.SolrError: Solr responded with an error (HTTP 404): [Reason: Error 404 Not Found]
ERROR 2021-12-03 19:24:58,857 solr_backend 121 140304664143616 Failed to query Solr using 'latest:(true)': Solr responded with an error (HTTP 404): [Reason: Error 404 Not Found]
Traceback (most recent call last):
  File "/home/indy/.pyenv/versions/3.6.8/lib/python3.6/site-packages/haystack/backends/solr_backend.py", line 138, in search
    raw_results = self.conn.search(query_string, **search_kwargs)
  File "/home/indy/.pyenv/versions/3.6.8/lib/python3.6/site-packages/pysolr.py", line 827, in search
    response = self._select(params, handler=search_handler)
  File "/home/indy/.pyenv/versions/3.6.8/lib/python3.6/site-packages/pysolr.py", line 488, in _select
    return self._send_request("get", path)
  File "/home/indy/.pyenv/versions/3.6.8/lib/python3.6/site-packages/pysolr.py", line 463, in _send_request
    raise SolrError(error_message % (resp.status_code, solr_message))
pysolr.SolrError: Solr responded with an error (HTTP 404): [Reason: Error 404 Not Found]
ERROR 2021-12-03 19:24:59,109 solr_backend 121 140304664143616 Failed to query Solr using 'create_timestamp:(["2021-12-02T19:24:58.729736Z" TO *])': Solr responded with an error (HTTP 404): [Reason: Error 404 Not Found]
Traceback (most recent call last):
  File "/home/indy/.pyenv/versions/3.6.8/lib/python3.6/site-packages/haystack/backends/solr_backend.py", line 138, in search
    raw_results = self.conn.search(query_string, **search_kwargs)
  File "/home/indy/.pyenv/versions/3.6.8/lib/python3.6/site-packages/pysolr.py", line 827, in search
    response = self._select(params, handler=search_handler)
  File "/home/indy/.pyenv/versions/3.6.8/lib/python3.6/site-packages/pysolr.py", line 488, in _select
    return self._send_request("get", path)
  File "/home/indy/.pyenv/versions/3.6.8/lib/python3.6/site-packages/pysolr.py", line 463, in _send_request
    raise SolrError(error_message % (resp.status_code, solr_message))
pysolr.SolrError: Solr responded with an error (HTTP 404): [Reason: Error 404 Not Found]```