An exception occurred during task execution. To see the full traceback, use -vvv. The error was:     raise ApiException(http_resp=r)
fatal: [localhost]: FAILED! => {"changed": false, "module_stderr": "Traceback (most recent call last):\n  File \"/usr/local/lib/python3.5/dist-packages/openshift/dynamic/client.py\", line 42, in inner\n    resp = func(self, *args, **kwargs)\n  File \"/usr/local/lib/python3.5/dist-packages/openshift/dynamic/client.py\", line 245, in request\n    _return_http_data_only=params.get('_return_http_data_only', True)\n  File \"/usr/local/lib/python3.5/dist-packages/kubernetes/client/api_client.py\", line 345, in call_api\n    _preload_content, _request_timeout)\n  File \"/usr/local/lib/python3.5/dist-packages/kubernetes/client/api_client.py\", line 176, in __call_api\n    _request_timeout=_request_timeout)\n  File \"/usr/local/lib/python3.5/dist-packages/kubernetes/client/api_client.py\", line 366, in request\n    headers=headers)\n  File \"/usr/local/lib/python3.5/dist-packages/kubernetes/client/rest.py\", line 241, in GET\n    query_params=query_params)\n  File \"/usr/local/lib/python3.5/dist-packages/kubernetes/client/rest.py\", line 231, in request\n    raise ApiException(http_resp=r)\nkubernetes.client.rest.ApiException: (401)\nReason: Unauthorized\nHTTP response headers: HTTPHeaderDict({'Content-Length': '129', 'Content-Type': 'application/json', 'Date': 'Thu, 04 Jun 2020 01:46:16 GMT'})\nHTTP response body: b'{\"kind\":\"Status\",\"apiVersion\":\"v1\",\"metadata\":{},\"status\":\"Failure\",\"message\":\"Unauthorized\",\"reason\":\"Unauthorized\",\"code\":401}\\n'\n\n\nDuring handling of the above exception, another exception occurred:\n\nTraceback (most recent call last):\n  File \"/root/.ansible/tmp/ansible-tmp-1591235174.834813-1032-106754695849049/AnsiballZ_k8s_info.py\", line 102, in <module>\n    _ansiballz_main()\n  File \"/root/.ansible/tmp/ansible-tmp-1591235174.834813-1032-106754695849049/AnsiballZ_k8s_info.py\", line 94, in _ansiballz_main\n    invoke_module(zipped_mod, temp_path, ANSIBALLZ_PARAMS)\n  File \"/root/.ansible/tmp/ansible-tmp-1591235174.834813-1032-106754695849049/AnsiballZ_k8s_info.py\", line 40, in invoke_module\n    runpy.run_module(mod_name='ansible.modules.clustering.k8s.k8s_info', init_globals=None, run_name='__main__', alter_sys=True)\n  File \"/usr/lib/python3.5/runpy.py\", line 196, in run_module\n    return _run_module_code(code, init_globals, run_name, mod_spec)\n  File \"/usr/lib/python3.5/runpy.py\", line 96, in _run_module_code\n    mod_name, mod_spec, pkg_name, script_name)\n  File \"/usr/lib/python3.5/runpy.py\", line 85, in _run_code\n    exec(code, run_globals)\n  File \"/tmp/ansible_k8s_info_payload_qioze4w_/ansible_k8s_info_payload.zip/ansible/modules/clustering/k8s/k8s_info.py\", line 179, in <module>\n  File \"/tmp/ansible_k8s_info_payload_qioze4w_/ansible_k8s_info_payload.zip/ansible/modules/clustering/k8s/k8s_info.py\", line 175, in main\n  File \"/tmp/ansible_k8s_info_payload_qioze4w_/ansible_k8s_info_payload.zip/ansible/modules/clustering/k8s/k8s_info.py\", line 148, in execute_module\n  File \"/tmp/ansible_k8s_info_payload_qioze4w_/ansible_k8s_info_payload.zip/ansible/module_utils/k8s/common.py\", line 200, in get_api_client\n  File \"/usr/local/lib/python3.5/dist-packages/openshift/dynamic/client.py\", line 71, in __init__\n    self.__discoverer = discoverer(self, cache_file)\n  File \"/usr/local/lib/python3.5/dist-packages/openshift/dynamic/discovery.py\", line 259, in __init__\n    Discoverer.__init__(self, client, cache_file)\n  File \"/usr/local/lib/python3.5/dist-packages/openshift/dynamic/discovery.py\", line 31, in __init__\n    self.__init_cache()\n  File \"/usr/local/lib/python3.5/dist-packages/openshift/dynamic/discovery.py\", line 78, in __init_cache\n    self._load_server_info()\n  File \"/usr/local/lib/python3.5/dist-packages/openshift/dynamic/discovery.py\", line 158, in _load_server_info\n    'kubernetes': self.client.request('get', '/version', serializer=just_json)\n  File \"/usr/local/lib/python3.5/dist-packages/openshift/dynamic/client.py\", line 44, in inner\n    raise api_exception(e)\nopenshift.dynamic.exceptions.UnauthorizedError: 401\nReason: Unauthorized\nHTTP response headers: HTTPHeaderDict({'Content-Length': '129', 'Content-Type': 'application/json', 'Date': 'Thu, 04 Jun 2020 01:46:16 GMT'})\nHTTP response body: b'{\"kind\":\"Status\",\"apiVersion\":\"v1\",\"metadata\":{},\"status\":\"Failure\",\"message\":\"Unauthorized\",\"reason\":\"Unauthorized\",\"code\":401}\\n'\nOriginal traceback: \n  File \"/usr/local/lib/python3.5/dist-packages/openshift/dynamic/client.py\", line 42, in inner\n    resp = func(self, *args, **kwargs)\n\n  File \"/usr/local/lib/python3.5/dist-packages/openshift/dynamic/client.py\", line 245, in request\n    _return_http_data_only=params.get('_return_http_data_only', True)\n\n  File \"/usr/local/lib/python3.5/dist-packages/kubernetes/client/api_client.py\", line 345, in call_api\n    _preload_content, _request_timeout)\n\n  File \"/usr/local/lib/python3.5/dist-packages/kubernetes/client/api_client.py\", line 176, in __call_api\n    _request_timeout=_request_timeout)\n\n  File \"/usr/local/lib/python3.5/dist-packages/kubernetes/client/api_client.py\", line 366, in request\n    headers=headers)\n\n  File \"/usr/local/lib/python3.5/dist-packages/kubernetes/client/rest.py\", line 241, in GET\n    query_params=query_params)\n\n  File \"/usr/local/lib/python3.5/dist-packages/kubernetes/client/rest.py\", line 231, in request\n    raise ApiException(http_resp=r)\n\n", "module_stdout": "", "msg": "MODULE FAILURE\nSee stdout/stderr for the exact error", "rc": 1}