2021-02-10 22:04:35,164|ERROR|base_events.py|Task exception was never retrieved
future: <Task finished name='Task-30' coro=<_createServer.<locals>._handle() done, defined at /home/ryan/indy/indy-node/indy_node/test/pool_restart/helper.py:40> exception=InvalidStateError('invalid state')>
Traceback (most recent call last):
  File "/home/ryan/indy/indy-node/indy_node/test/pool_restart/helper.py", line 43, in _handle
	indicator.set_result(request)
asyncio.exceptions.InvalidStateError: invalid state
2021-02-10 22:04:35,165|ERROR|base_events.py|Task exception was never retrieved
future: <Task finished name='Task-31' coro=<_createServer.<locals>._handle() done, defined at /home/ryan/indy/indy-node/indy_node/test/pool_restart/helper.py:40> exception=InvalidStateError('invalid state')>
Traceback (most recent call last):
  File "/home/ryan/indy/indy-node/indy_node/test/pool_restart/helper.py", line 43, in _handle
	indicator.set_result(request)
asyncio.exceptions.InvalidStateError: invalid state
2021-02-10 22:04:35,165|ERROR|base_events.py|Task exception was never retrieved
future: <Task finished name='Task-32' coro=<_createServer.<locals>._handle() done, defined at /home/ryan/indy/indy-node/indy_node/test/pool_restart/helper.py:40> exception=InvalidStateError('invalid state')>
Traceback (most recent call last):
  File "/home/ryan/indy/indy-node/indy_node/test/pool_restart/helper.py", line 43, in _handle
	indicator.set_result(request)
asyncio.exceptions.InvalidStateError: invalid state
2021-02-10 22:04:35,180|INFO|motor.py|Delta changing status from started to stopping
2021-02-10 22:04:35,180|INFO|node.py|node Delta current stats
--------------------------------------------------------
node inbox size     	: 0
client inbox size   	: 0
age (seconds)       	: 5.468867540359497
next check for reconnect: -10.616118880003341
node connections    	: {'Beta', 'Gamma', 'Alpha'}
f                   	: 1
master instance     	: 0
replicas            	: 2
view no             	: 0
rank                	: 3
msgs to replicas    	: 0
action queue        	: 0 140285524325856
action queue stash  	: 4 140285524325952
2021-02-10 22:04:35,180|INFO|node.py|Delta reseting...
2021-02-10 22:04:35,180|DEBUG|node.py|Delta clearing aqStash of size 4
2021-02-10 22:04:35,207|NOTIFICATION|zstack.py|stack Delta closing its listener
2021-02-10 22:04:35,208|DEBUG|zstack.py|Delta starting to disconnect remotes
2021-02-10 22:04:35,208|DEBUG|remote.py|disconnecting remote Beta:HA(host='127.0.0.1', port=6258)
2021-02-10 22:04:35,209|TRACE|remote.py|Beta:HA(host='127.0.0.1', port=6258) closing monitor socket
2021-02-10 22:04:35,210|TRACE|remote.py|disconnecting socket 554
2021-02-10 22:04:35,210|DEBUG|remote.py|disconnecting remote Gamma:HA(host='127.0.0.1', port=6260)
2021-02-10 22:04:35,210|TRACE|remote.py|Gamma:HA(host='127.0.0.1', port=6260) closing monitor socket
2021-02-10 22:04:35,210|TRACE|remote.py|disconnecting socket 558
2021-02-10 22:04:35,211|DEBUG|remote.py|disconnecting remote Alpha:HA(host='127.0.0.1', port=6256)
2021-02-10 22:04:35,211|TRACE|remote.py|Alpha:HA(host='127.0.0.1', port=6256) closing monitor socket
2021-02-10 22:04:35,211|TRACE|remote.py|disconnecting socket 562
2021-02-10 22:04:35,211|DEBUG|authenticator.py|Stopping ZAP at b'inproc://zeromq.zap.7'
2021-02-10 22:04:35,211|NOTIFICATION|zstack.py|stack Delta stopped
2021-02-10 22:04:35,211|NOTIFICATION|zstack.py|stack DeltaC closing its listener
2021-02-10 22:04:35,212|DEBUG|zstack.py|DeltaC starting to disconnect remotes
2021-02-10 22:04:35,213|DEBUG|authenticator.py|Stopping ZAP at b'inproc://zeromq.zap.8'
2021-02-10 22:04:35,213|NOTIFICATION|zstack.py|stack DeltaC stopped
2021-02-10 22:04:35,213|INFO|node.py|Delta closing key-value storages
2021-02-10 22:04:35,245|DEBUG|helper.py|Error while dropping db Delta: 'SpyableTestNode' object has no attribute 'graphStore'
2021-02-10 22:04:35,245|INFO|motor.py|Delta changing status from stopping to stopped
2021-02-10 22:04:35,248|INFO|motor.py|Gamma changing status from started to stopping
2021-02-10 22:04:35,253|INFO|node.py|node Gamma current stats
--------------------------------------------------------
node inbox size     	: 0
client inbox size   	: 0
age (seconds)       	: 6.80866813659668
next check for reconnect: -10.513512154997443
node connections    	: {'Beta', 'Alpha', 'Delta'}
f                   	: 1
master instance     	: 0
replicas            	: 2
view no             	: 0
rank                	: 2
msgs to replicas    	: 0
action queue        	: 0 140285524929216
action queue stash  	: 4 140285524929120
2021-02-10 22:04:35,253|INFO|node.py|Gamma reseting...
2021-02-10 22:04:35,253|DEBUG|node.py|Gamma clearing aqStash of size 4
2021-02-10 22:04:35,256|NOTIFICATION|zstack.py|stack Gamma closing its listener
2021-02-10 22:04:35,257|DEBUG|zstack.py|Gamma starting to disconnect remotes
2021-02-10 22:04:35,257|DEBUG|remote.py|disconnecting remote Beta:HA(host='127.0.0.1', port=6258)
2021-02-10 22:04:35,257|TRACE|remote.py|Beta:HA(host='127.0.0.1', port=6258) closing monitor socket
2021-02-10 22:04:35,258|TRACE|remote.py|disconnecting socket 542
2021-02-10 22:04:35,258|DEBUG|remote.py|disconnecting remote Alpha:HA(host='127.0.0.1', port=6256)
2021-02-10 22:04:35,258|TRACE|remote.py|Alpha:HA(host='127.0.0.1', port=6256) closing monitor socket
2021-02-10 22:04:35,258|TRACE|remote.py|disconnecting socket 546
2021-02-10 22:04:35,258|DEBUG|remote.py|disconnecting remote Delta:HA(host='127.0.0.1', port=6262)
2021-02-10 22:04:35,258|TRACE|remote.py|Delta:HA(host='127.0.0.1', port=6262) closing monitor socket
2021-02-10 22:04:35,262|TRACE|remote.py|disconnecting socket 550
2021-02-10 22:04:35,262|DEBUG|authenticator.py|Stopping ZAP at b'inproc://zeromq.zap.5'
2021-02-10 22:04:35,262|NOTIFICATION|zstack.py|stack Gamma stopped
2021-02-10 22:04:35,263|NOTIFICATION|zstack.py|stack GammaC closing its listener
2021-02-10 22:04:35,263|DEBUG|zstack.py|GammaC starting to disconnect remotes
2021-02-10 22:04:35,263|DEBUG|authenticator.py|Stopping ZAP at b'inproc://zeromq.zap.6'
2021-02-10 22:04:35,263|NOTIFICATION|zstack.py|stack GammaC stopped
2021-02-10 22:04:35,263|INFO|node.py|Gamma closing key-value storages
2021-02-10 22:04:35,281|DEBUG|helper.py|Error while dropping db Gamma: 'SpyableTestNode' object has no attribute 'graphStore'
2021-02-10 22:04:35,281|INFO|motor.py|Gamma changing status from stopping to stopped
2021-02-10 22:04:35,281|INFO|motor.py|Beta changing status from started to stopping
2021-02-10 22:04:35,281|INFO|node.py|node Beta current stats
--------------------------------------------------------
node inbox size     	: 0
client inbox size   	: 0
age (seconds)       	: 8.190939903259277
next check for reconnect: -10.475150373997167
node connections    	: {'Gamma', 'Alpha', 'Delta'}
f                   	: 1
master instance     	: 0
replicas            	: 2
view no             	: 0
rank                	: 1
msgs to replicas    	: 0
action queue        	: 0 140285525220224
action queue stash  	: 4 140285525220320
2021-02-10 22:04:35,281|INFO|node.py|Beta reseting...
2021-02-10 22:04:35,282|DEBUG|node.py|Beta clearing aqStash of size 4
2021-02-10 22:04:35,285|NOTIFICATION|zstack.py|stack Beta closing its listener
2021-02-10 22:04:35,287|DEBUG|zstack.py|Beta starting to disconnect remotes
2021-02-10 22:04:35,287|DEBUG|remote.py|disconnecting remote Gamma:HA(host='127.0.0.1', port=6260)
2021-02-10 22:04:35,287|TRACE|remote.py|Gamma:HA(host='127.0.0.1', port=6260) closing monitor socket
2021-02-10 22:04:35,288|TRACE|remote.py|disconnecting socket 530
2021-02-10 22:04:35,289|DEBUG|remote.py|disconnecting remote Alpha:HA(host='127.0.0.1', port=6256)
2021-02-10 22:04:35,289|TRACE|remote.py|Alpha:HA(host='127.0.0.1', port=6256) closing monitor socket
2021-02-10 22:04:35,289|TRACE|remote.py|disconnecting socket 534
2021-02-10 22:04:35,295|DEBUG|remote.py|disconnecting remote Delta:HA(host='127.0.0.1', port=6262)
2021-02-10 22:04:35,295|TRACE|remote.py|Delta:HA(host='127.0.0.1', port=6262) closing monitor socket
2021-02-10 22:04:35,295|TRACE|remote.py|disconnecting socket 538
2021-02-10 22:04:35,295|DEBUG|authenticator.py|Stopping ZAP at b'inproc://zeromq.zap.3'
2021-02-10 22:04:35,295|NOTIFICATION|zstack.py|stack Beta stopped
2021-02-10 22:04:35,296|NOTIFICATION|zstack.py|stack BetaC closing its listener
2021-02-10 22:04:35,298|DEBUG|zstack.py|BetaC starting to disconnect remotes
2021-02-10 22:04:35,298|DEBUG|authenticator.py|Stopping ZAP at b'inproc://zeromq.zap.4'
2021-02-10 22:04:35,298|NOTIFICATION|zstack.py|stack BetaC stopped
2021-02-10 22:04:35,298|INFO|node.py|Beta closing key-value storages
2021-02-10 22:04:35,308|DEBUG|helper.py|Error while dropping db Beta: 'SpyableTestNode' object has no attribute 'graphStore'
2021-02-10 22:04:35,308|INFO|motor.py|Beta changing status from stopping to stopped
2021-02-10 22:04:35,308|INFO|motor.py|Alpha changing status from started to stopping
2021-02-10 22:04:35,308|INFO|node.py|node Alpha current stats
--------------------------------------------------------
node inbox size     	: 0
client inbox size   	: 0
age (seconds)       	: 9.607943058013916
next check for reconnect: -10.43794703399908
node connections    	: {'Beta', 'Gamma', 'Delta'}
f                   	: 1
master instance     	: 0
replicas            	: 2
view no             	: 0
rank                	: 0
msgs to replicas    	: 0
action queue        	: 0 140285526831744
action queue stash  	: 4 140285526831840
2021-02-10 22:04:35,308|INFO|node.py|Alpha reseting...
2021-02-10 22:04:35,308|DEBUG|node.py|Alpha clearing aqStash of size 4
2021-02-10 22:04:35,335|NOTIFICATION|zstack.py|stack Alpha closing its listener
2021-02-10 22:04:35,336|DEBUG|zstack.py|Alpha starting to disconnect remotes
2021-02-10 22:04:35,336|DEBUG|remote.py|disconnecting remote Beta:HA(host='127.0.0.1', port=6258)
2021-02-10 22:04:35,336|TRACE|remote.py|Beta:HA(host='127.0.0.1', port=6258) closing monitor socket
2021-02-10 22:04:35,336|TRACE|remote.py|disconnecting socket 518
2021-02-10 22:04:35,336|DEBUG|remote.py|disconnecting remote Gamma:HA(host='127.0.0.1', port=6260)
2021-02-10 22:04:35,336|TRACE|remote.py|Gamma:HA(host='127.0.0.1', port=6260) closing monitor socket
2021-02-10 22:04:35,336|TRACE|remote.py|disconnecting socket 522
2021-02-10 22:04:35,337|DEBUG|remote.py|disconnecting remote Delta:HA(host='127.0.0.1', port=6262)
2021-02-10 22:04:35,337|TRACE|remote.py|Delta:HA(host='127.0.0.1', port=6262) closing monitor socket
2021-02-10 22:04:35,337|TRACE|remote.py|disconnecting socket 526
2021-02-10 22:04:35,337|DEBUG|authenticator.py|Stopping ZAP at b'inproc://zeromq.zap.1'
2021-02-10 22:04:35,337|NOTIFICATION|zstack.py|stack Alpha stopped
2021-02-10 22:04:35,337|NOTIFICATION|zstack.py|stack AlphaC closing its listener
2021-02-10 22:04:35,337|DEBUG|zstack.py|AlphaC starting to disconnect remotes
2021-02-10 22:04:35,337|DEBUG|authenticator.py|Stopping ZAP at b'inproc://zeromq.zap.2'
2021-02-10 22:04:35,338|NOTIFICATION|zstack.py|stack AlphaC stopped
2021-02-10 22:04:35,338|INFO|node.py|Alpha closing key-value storages
2021-02-10 22:04:35,349|DEBUG|helper.py|Error while dropping db Alpha: 'SpyableTestNode' object has no attribute 'graphStore'
2021-02-10 22:04:35,364|INFO|motor.py|Alpha changing status from stopping to stopped
2021-02-10 22:04:35,365|NOTIFICATION|looper.py|Looper shutting down now...
2021-02-10 22:04:35,365|INFO|motor.py|Alpha is already stopped
2021-02-10 22:04:35,365|INFO|motor.py|Beta is already stopped
2021-02-10 22:04:35,365|INFO|motor.py|Gamma is already stopped
2021-02-10 22:04:35,365|INFO|motor.py|Delta is already stopped
2021-02-10 22:04:35,365|NOTIFICATION|looper.py|Looper shut down in 0.000 seconds.
2021-02-10 22:04:35,365|DEBUG|looper.py|Unsetting handler for SIGINT
2021-02-10 22:04:35,365|DEBUG|looper.py|Unsetting handler for SIGTERM
base_events.py        	1707 ERROR	Task exception was never retrieved
future: <Task finished name='Task-30' coro=<_createServer.<locals>._handle() done, defined at /home/ryan/indy/indy-node/indy_node/test/pool_restart/helper.py:40> exception=InvalidStateError('invalid state')>
Traceback (most recent call last):
  File "/home/ryan/indy/indy-node/indy_node/test/pool_restart/helper.py", line 43, in _handle
	indicator.set_result(request)
asyncio.exceptions.InvalidStateError: invalid state
base_events.py        	1707 ERROR	Task exception was never retrieved
future: <Task finished name='Task-31' coro=<_createServer.<locals>._handle() done, defined at /home/ryan/indy/indy-node/indy_node/test/pool_restart/helper.py:40> exception=InvalidStateError('invalid state')>
Traceback (most recent call last):
  File "/home/ryan/indy/indy-node/indy_node/test/pool_restart/helper.py", line 43, in _handle
	indicator.set_result(request)
asyncio.exceptions.InvalidStateError: invalid state
base_events.py        	1707 ERROR	Task exception was never retrieved
future: <Task finished name='Task-32' coro=<_createServer.<locals>._handle() done, defined at /home/ryan/indy/indy-node/indy_node/test/pool_restart/helper.py:40> exception=InvalidStateError('invalid state')>
Traceback (most recent call last):
  File "/home/ryan/indy/indy-node/indy_node/test/pool_restart/helper.py", line 43, in _handle
	indicator.set_result(request)
asyncio.exceptions.InvalidStateError: invalid state

indy_node/test/pool_restart/test_pool_restart.py:96 (test_pool_restart_in_view_change)
warnfilters = <function warnfilters.<locals>._ at 0x7f96c51b1dc0>

	@pytest.yield_fixture(scope="session", autouse=True)
	def warncheck(warnfilters):
    	with WarningsRecorder() as record:
        	warnfilters()
        	yield
        	gc.collect()
    	to_prints = []
    
    	def keyfunc(_):
        	return _.category.__name__, _.filename, _.lineno
    
    	_sorted = sorted(record, key=keyfunc)
    	_grouped = itertools.groupby(_sorted, keyfunc)
    	for k, g in _grouped:
        	to_prints.append("\n"
                         	"category: {}\n"
                         	"filename: {}\n"
                         	"  lineno: {}".format(*k))
        	messages = itertools.groupby(g, lambda _: str(_.message))
        	for k2, g2 in messages:
            	count = sum(1 for _ in g2)
            	count_str = ' ({} times)'.format(count) if count > 1 else ''
            	to_prints.append(" 	msg: {}{}".format(k2, count_str))
    	if to_prints:
        	to_prints.insert(0, 'Warnings found:')
>       	pytest.fail('\n'.join(to_prints))
E       	Failed: Warnings found:
E      	 
E       	category: ResourceWarning
E       	filename: /usr/lib/python3.8/enum.py
E         	lineno: 309
E            	msg: unclosed <socket.socket fd=645, family=AddressFamily.AF_INET, type=SocketKind.SOCK_STREAM, proto=6, laddr=('127.0.0.1', 30003), raddr=('127.0.0.1', 49842)>

../../../../indy-plenum/plenum/test/conftest.py:163: Failed